<sdf version='1.6'>
  <model name='ABB_IRB120'>

    <joint name="fixed to ground" type="fixed">
      <parent>world</parent>
      <child>BASE</child>
    </joint>


    <link name='BASE'>
      <pose frame=''>0 0 0 0 -0 0</pose>
      <inertial>
        <pose frame=''>-0.042 0 0.08 0 -0 0</pose>
        <mass>6.215</mass>
        <inertia>
          <ixx>0.025</ixx>
          <ixy>0</ixy>
          <ixz>0.001</ixz>
          <iyy>0.049</iyy>
          <iyz>0</iyz>
          <izz>0.047</izz>
        </inertia>
      </inertial>
      <collision name='BASE_collision'>
        <pose frame=''>0 0 0 0 -0 0</pose>
        <geometry>
          <mesh>
            <scale>1 1 1</scale>
            <uri>model://ABB_IRB120/meshes/BASE.STL</uri>
          </mesh>
        </geometry>
      </collision>
      <visual name='BASE_visual'>
        <pose frame=''>0 0 0 0 -0 0</pose>
        <geometry>
          <mesh>
            <scale>1 1 1</scale>
            <uri>model://ABB_IRB120/meshes/BASE.STL</uri>
          </mesh>
        </geometry>
        <material>
       <ambient>255 128 0 1</ambient>
       <diffuse>1 1 1 1</diffuse>
       <emissive>0 0 0 1</emissive>
       <specular>0 0 0 1</specular>
       </material>
      </visual>
    </link>
    <link name='LINK1'>
      <pose frame=''>0 0 0.168 0 -0 0</pose>
      <inertial>
        <pose frame=''>0 0 0.07 0 -0 0</pose>
        <mass>3.067</mass>
        <inertia>
          <ixx>0.014</ixx>
          <ixy>0</ixy>
          <ixz>0</ixz>
          <iyy>0.014</iyy>
          <iyz>0</iyz>
          <izz>0.01</izz>
        </inertia>
      </inertial>
      <collision name='LINK1_collision'>
        <pose frame=''>0 0 0 0 -0 0</pose>
        <geometry>
          <mesh>
            <scale>1 1 1</scale>
            <uri>model://ABB_IRB120/meshes/LINK1.STL</uri>
          </mesh>
        </geometry>
      </collision>
      <visual name='LINK1_visual'>
        <pose frame=''>0 0 0 0 -0 0</pose>
        <geometry>
          <mesh>
            <scale>1 1 1</scale>
            <uri>model://ABB_IRB120/meshes/LINK1.STL</uri>
          </mesh>
        </geometry>
        <material>
       <ambient>255 128 0 1</ambient>
       <diffuse>1 1 1 1</diffuse>
       <emissive>0 0 0 1</emissive>
       <specular>0 0 0 1</specular>
       </material>
      </visual>
    </link>
    <joint name='LINK1_JOINT' type='revolute'>
      <child>LINK1</child>
      <parent>BASE</parent>
      <axis>
        <xyz>0 0 1</xyz>
        <limit>
          <lower>-3.141592</lower>
          <upper>3.141592</upper>
        </limit>
        <dynamics>
          <spring_reference>0</spring_reference>
          <spring_stiffness>0</spring_stiffness>
        </dynamics>
        <use_parent_model_frame>1</use_parent_model_frame>
      </axis>
    </joint>
    <link name='LINK2'>
      <pose frame=''>0 0 0.29 0 -0 0</pose>
      <inertial>
        <pose frame=''>-0.001 0.002 0.101 0 -0 0</pose>
        <mass>3.909</mass>
        <inertia>
          <ixx>0.06</ixx>
          <ixy>0</ixy>
          <ixz>0</ixz>
          <iyy>0.042</iyy>
          <iyz>0.001</iyz>
          <izz>0.026</izz>
        </inertia>
      </inertial>
      <collision name='LINK2_collision'>
        <pose frame=''>0 0 0 0 -0 0</pose>
        <geometry>
          <mesh>
            <scale>1 1 1</scale>
            <uri>model://ABB_IRB120/meshes/LINK2.STL</uri>
          </mesh>
        </geometry>
      </collision>
      <visual name='LINK2_visual'>
        <pose frame=''>0 0 0 0 -0 0</pose>
        <geometry>
          <mesh>
            <scale>1 1 1</scale>
            <uri>model://ABB_IRB120/meshes/LINK2.STL</uri>
          </mesh>
        </geometry>
        <material>
       <ambient>255 128 0 1</ambient>
       <diffuse>1 1 1 1</diffuse>
       <emissive>0 0 0 1</emissive>
       <specular>0 0 0 1</specular>
       </material>
      </visual>
    </link>
    <joint name='LINK2_JOINT' type='revolute'>
      <child>LINK2</child>
      <parent>LINK1</parent>
      <axis>
        <xyz>0 1 0</xyz>
        <limit>
          <lower>-3.141592</lower>
          <upper>3.141592</upper>
        </limit>
        <dynamics>
          <spring_reference>0</spring_reference>
          <spring_stiffness>0</spring_stiffness>
        </dynamics>
        <use_parent_model_frame>1</use_parent_model_frame>
      </axis>
    </joint>
    <link name='LINK3'>
      <pose frame=''>0 0 0.56 0 -0 0</pose>
      <inertial>
        <pose frame=''>0.023 -0.001 0.058 0 -0 0</pose>
        <mass>2.92</mass>
        <inertia>
          <ixx>0.008</ixx>
          <ixy>0</ixy>
          <ixz>0.001</ixz>
          <iyy>0.017</iyy>
          <iyz>0</iyz>
          <izz>0.013</izz>
        </inertia>
      </inertial>
      <collision name='LINK3_collision'>
        <pose frame=''>0 0 0 0 -0 0</pose>
        <geometry>
          <mesh>
            <scale>1 1 1</scale>
            <uri>model://ABB_IRB120/meshes/LINK3.STL</uri>
          </mesh>
        </geometry>
      </collision>
      <visual name='LINK3_visual'>
        <pose frame=''>0 0 0 0 -0 0</pose>
        <geometry>
          <mesh>
            <scale>1 1 1</scale>
            <uri>model://ABB_IRB120/meshes/LINK3.STL</uri>
          </mesh>
        </geometry>
        <material>
       <ambient>255 128 0 1</ambient>
       <diffuse>1 1 1 1</diffuse>
       <emissive>0 0 0 1</emissive>
       <specular>0 0 0 1</specular>
       </material>
      </visual>
    </link>
    <joint name='LINK3_JOINT' type='revolute'>
      <child>LINK3</child>
      <parent>LINK2</parent>
      <axis>
        <xyz>0 1 0</xyz>
          <limit>
          <lower>-3.141592</lower>
          <upper>3.141592</upper>
        </limit>
        <dynamics>
          <spring_reference>0</spring_reference>
          <spring_stiffness>0</spring_stiffness>
        </dynamics>
        <use_parent_model_frame>1</use_parent_model_frame>
      </axis>
    </joint>
    <link name='LINK4'>
      <pose frame=''>0.15 0 0.63 0 -0 0</pose>
      <inertial>
        <pose frame=''>0.076 -0.005 0 0 -0 0</pose>
        <mass>1.448</mass>
        <inertia>
          <ixx>0.003</ixx>
          <ixy>0</ixy>
          <ixz>0</ixz>
          <iyy>0.004</iyy>
          <iyz>0</iyz>
          <izz>0.006</izz>
        </inertia>
      </inertial>
      <collision name='LINK4_collision'>
        <pose frame=''>0 0 0 0 -0 0</pose>
        <geometry>
          <mesh>
            <scale>1 1 1</scale>
            <uri>model://ABB_IRB120/meshes/LINK4.STL</uri>
          </mesh>
        </geometry>
      </collision>
      <visual name='LINK4_visual'>
        <pose frame=''>0 0 0 0 -0 0</pose>
        <geometry>
          <mesh>
            <scale>1 1 1</scale>
            <uri>model://ABB_IRB120/meshes/LINK4.STL</uri>
          </mesh>
        </geometry>
        <material>
       <ambient>255 128 0 1</ambient>
       <diffuse>1 1 1 1</diffuse>
       <emissive>0 0 0 1</emissive>
       <specular>0 0 0 1</specular>
       </material>
      </visual>
    </link>
    <joint name='LINK4_JOINT' type='revolute'>
      <child>LINK4</child>
      <parent>LINK3</parent>
      <axis>
        <xyz>1 0 0</xyz>
          <limit>
          <lower>-3.141592</lower>
          <upper>3.141592</upper>
        </limit>
        <dynamics>
          <spring_reference>0</spring_reference>
          <spring_stiffness>0</spring_stiffness>
        </dynamics>
        <use_parent_model_frame>1</use_parent_model_frame>
      </axis>
    </joint>
    <link name='LINK5'>
      <pose frame=''>0.302 0 0.63 0 -0 0</pose>
      <inertial>
        <pose frame=''>-0.001 0 0 0 -0 0</pose>
        <mass>0.547</mass>
        <inertia>
          <ixx>0</ixx>
          <ixy>0</ixy>
          <ixz>0</ixz>
          <iyy>0.001</iyy>
          <iyz>0</iyz>
          <izz>0.001</izz>
        </inertia>
      </inertial>
      <collision name='LINK5_collision'>
        <pose frame=''>0 0 0 0 -0 0</pose>
        <geometry>
          <mesh>
            <scale>1 1 1</scale>
            <uri>model://ABB_IRB120/meshes/LINK5.STL</uri>
          </mesh>
        </geometry>
      </collision>
      <visual name='LINK5_visual'>
        <pose frame=''>0 0 0 0 -0 0</pose>
        <geometry>
          <mesh>
            <scale>1 1 1</scale>
            <uri>model://ABB_IRB120/meshes/LINK5.STL</uri>
          </mesh>
        </geometry>
          <material>
         <ambient>255 128 0 1</ambient>
         <diffuse>1 1 1 1</diffuse>
         <emissive>0 0 0 1</emissive>
         <specular>0 0 0 1</specular>
         </material>
      </visual>
    </link>
    <joint name='LINK5_JOINT' type='revolute'>
      <child>LINK5</child>
      <parent>LINK4</parent>
      <axis>
        <xyz>0 1 0</xyz>
          <limit>
          <lower>-3.141592</lower>
          <upper>3.141592</upper>
        </limit>
        <dynamics>
          <spring_reference>0</spring_reference>
          <spring_stiffness>0</spring_stiffness>
        </dynamics>
        <use_parent_model_frame>1</use_parent_model_frame>
      </axis>
    </joint>
    <link name='LINK6'>
      <pose frame=''>0.374 0 0.63 0 -0 0</pose>
      <inertial>
        <pose frame=''>-0.007 0 0 0 -0 0</pose>
        <mass>0.014</mass>
        <inertia>
          <ixx>0</ixx>
          <ixy>0</ixy>
          <ixz>0</ixz>
          <iyy>0</iyy>
          <iyz>0</iyz>
          <izz>0</izz>
        </inertia>
      </inertial>
      <collision name='LINK6_collision'>
        <pose frame=''>0 0 0 0 -0 0</pose>
        <geometry>
          <mesh>
            <scale>1 1 1</scale>
            <uri>model://ABB_IRB120/meshes/LINK6.STL</uri>
          </mesh>
        </geometry>
      </collision>
      <visual name='LINK6_visual'>
        <pose frame=''>0 0 0 0 -0 0</pose>
        <geometry>
          <mesh>
            <scale>1 1 1</scale>
            <uri>model://ABB_IRB120/meshes/LINK6.STL</uri>
          </mesh>
        </geometry>
        <material>
       <ambient>0 0 0 1</ambient>
       <diffuse>1 1 1 1</diffuse>
       <emissive>0 0 0 1</emissive>
       <specular>0 0 0 1</specular>
       </material>
      </visual>
    </link>
    <joint name='LINK6_JOINT' type='revolute'>
      <child>LINK6</child>
      <parent>LINK5</parent>
      <axis>
        <xyz>1 0 0</xyz>
        <limit>
          <lower>-3.141592</lower>
          <upper>3.141592</upper>
        </limit>
        <dynamics>
          <spring_reference>0</spring_reference>
          <spring_stiffness>0</spring_stiffness>
        </dynamics>
        <use_parent_model_frame>1</use_parent_model_frame>
      </axis>
    </joint>
  </model>
</sdf>
